Workbook

Sheet WBS主表
A1: 阶段 | B1: WBS编号 | C1: 任务名称(交付物) | D1: WBS词典说明(含/不含) | E1: 交付物/验收标准(DoD) | F1: 责任人 | G1: 里程碑 | H1: 前置任务(WBS号) | I1: 计划开始 | J1: 计划结束 | K1: 实际开始 | L1: 实际结束 | M1: 进度偏差(天) | N1: 完成度% | O1: 状态 | P1: 备注
A2: 1.立项 | B2: 1 | C2: 项目立项与准备 | D2: 含商业论证、立项审批、PMO启动；不含供应商选型 | E2: 项目立项书获批 | G2: 否 | M2: =IFERROR(IF(OR(J2="",L2=""),"",L2-J2),"") | O2: =IF(N2=100,"已完成",IF(AND(N2=0,J2<>"",TODAY()>J2),"已延期",IF(N2=0,"未开始",IF(AND(J2<>"",TODAY()>J2),"已延期","进行中")))) -> 未开始
A3: 1.立项 | B3: 1.1 | C3: 立项文件 | D3: 含需求背景、预算、收益测算 | E3: 立项书、预算书评审通过 | G3: 否 | M3: =IFERROR(IF(OR(J3="",L3=""),"",L3-J3),"") | O3: =IF(N3=100,"已完成",IF(AND(N3=0,J3<>"",TODAY()>J3),"已延期",IF(N3=0,"未开始",IF(AND(J3<>"",TODAY()>J3),"已延期","进行中")))) -> 未开始
A4: 1.立项 | B4: 1.1.1 | C4: 业务需求说明书(BRD) | D4: 业务方需求、痛点、目标 | E4: BRD签字确认 | G4: 否 | M4: =IFERROR(IF(OR(J4="",L4=""),"",L4-J4),"") | O4: =IF(N4=100,"已完成",IF(AND(N4=0,J4<>"",TODAY()>J4),"已延期",IF(N4=0,"未开始",IF(AND(J4<>"",TODAY()>J4),"已延期","进行中")))) -> 未开始
A5: 1.立项 | B5: 1.1.2 | C5: 项目预算与收益测算 | D5: TCO、ROI测算 | E5: 预算获财务批准 | G5: 否 | H5: 1.1.1 | M5: =IFERROR(IF(OR(J5="",L5=""),"",L5-J5),"") | O5: =IF(N5=100,"已完成",IF(AND(N5=0,J5<>"",TODAY()>J5),"已延期",IF(N5=0,"未开始",IF(AND(J5<>"",TODAY()>J5),"已延期","进行中")))) -> 未开始
A6: 1.立项 | B6: 1.1.3 | C6: 立项评审与审批 | D6: 立项会材料与决议 | E6: 立项书获批(里程碑) | G6: 是 | H6: 1.1.2 | M6: =IFERROR(IF(OR(J6="",L6=""),"",L6-J6),"") | O6: =IF(N6=100,"已完成",IF(AND(N6=0,J6<>"",TODAY()>J6),"已延期",IF(N6=0,"未开始",IF(AND(J6<>"",TODAY()>J6),"已延期","进行中")))) -> 未开始
A7: 1.立项 | B7: 1.2 | C7: 项目治理与启动 | D7: 含章程、组织、计划、PMO机制 | E7: 项目章程发布 | G7: 否 | H7: 1.1.3 | M7: =IFERROR(IF(OR(J7="",L7=""),"",L7-J7),"") | O7: =IF(N7=100,"已完成",IF(AND(N7=0,J7<>"",TODAY()>J7),"已延期",IF(N7=0,"未开始",IF(AND(J7<>"",TODAY()>J7),"已延期","进行中")))) -> 未开始
A8: 1.立项 | B8: 1.2.1 | C8: 项目章程 | D8: 目标、范围、组织、干系人 | E8: 章程签发 | G8: 否 | M8: =IFERROR(IF(OR(J8="",L8=""),"",L8-J8),"") | O8: =IF(N8=100,"已完成",IF(AND(N8=0,J8<>"",TODAY()>J8),"已延期",IF(N8=0,"未开始",IF(AND(J8<>"",TODAY()>J8),"已延期","进行中")))) -> 未开始
A9: 1.立项 | B9: 1.2.2 | C9: 项目管理计划(含WBS/进度/风险) | D9: 进度、沟通、风险、变更管理计划 | E9: 计划评审通过 | G9: 否 | H9: 1.2.1 | M9: =IFERROR(IF(OR(J9="",L9=""),"",L9-J9),"") | O9: =IF(N9=100,"已完成",IF(AND(N9=0,J9<>"",TODAY()>J9),"已延期",IF(N9=0,"未开始",IF(AND(J9<>"",TODAY()>J9),"已延期","进行中")))) -> 未开始
A10: 1.立项 | B10: 1.2.3 | C10: 项目启动会(Kick-off) | D10: 内外部团队、职责、里程碑宣贯 | E10: 会议纪要发布 | G10: 是 | H10: 1.2.2 | M10: =IFERROR(IF(OR(J10="",L10=""),"",L10-J10),"") | O10: =IF(N10=100,"已完成",IF(AND(N10=0,J10<>"",TODAY()>J10),"已延期",IF(N10=0,"未开始",IF(AND(J10<>"",TODAY()>J10),"已延期","进行中")))) -> 未开始
A11: 2.选型 | B11: 2 | C11: 供应商选型与合同 | D11: 含RFP、评标、商务谈判、签约；不含实施交付 | E11: 合同签署生效 | G11: 否 | H11: 1.1.3 | M11: =IFERROR(IF(OR(J11="",L11=""),"",L11-J11),"") | O11: =IF(N11=100,"已完成",IF(AND(N11=0,J11<>"",TODAY()>J11),"已延期",IF(N11=0,"未开始",IF(AND(J11<>"",TODAY()>J11),"已延期","进行中")))) -> 未开始
A12: 2.选型 | B12: 2.1 | C12: 需求与招标文件 | D12: 含RFP、技术规格、评分标准 | E12: RFP发布 | G12: 否 | M12: =IFERROR(IF(OR(J12="",L12=""),"",L12-J12),"") | O12: =IF(N12=100,"已完成",IF(AND(N12=0,J12<>"",TODAY()>J12),"已延期",IF(N12=0,"未开始",IF(AND(J12<>"",TODAY()>J12),"已延期","进行中")))) -> 未开始
A13: 2.选型 | B13: 2.1.1 | C13: 需求规格说明书(SRS/技术规格) | D13: 功能、非功能、接口、性能要求 | E13: SRS评审通过 | G13: 否 | M13: =IFERROR(IF(OR(J13="",L13=""),"",L13-J13),"") | O13: =IF(N13=100,"已完成",IF(AND(N13=0,J13<>"",TODAY()>J13),"已延期",IF(N13=0,"未开始",IF(AND(J13<>"",TODAY()>J13),"已延期","进行中")))) -> 未开始
A14: 2.选型 | B14: 2.1.2 | C14: RFP招标文件与评分标准 | D14: 商务/技术/服务评分权重 | E14: RFP定稿发布 | G14: 否 | H14: 2.1.1 | M14: =IFERROR(IF(OR(J14="",L14=""),"",L14-J14),"") | O14: =IF(N14=100,"已完成",IF(AND(N14=0,J14<>"",TODAY()>J14),"已延期",IF(N14=0,"未开始",IF(AND(J14<>"",TODAY()>J14),"已延期","进行中")))) -> 未开始
A15: 2.选型 | B15: 2.2 | C15: 供应商评估与选定 | D15: 含答标、POC、评标 | E15: 中选供应商确定 | G15: 否 | H15: 2.1.2 | M15: =IFERROR(IF(OR(J15="",L15=""),"",L15-J15),"") | O15: =IF(N15=100,"已完成",IF(AND(N15=0,J15<>"",TODAY()>J15),"已延期",IF(N15=0,"未开始",IF(AND(J15<>"",TODAY()>J15),"已延期","进行中")))) -> 未开始
A16: 2.选型 | B16: 2.2.1 | C16: 供应商答标与产品演示 | D16: 候选厂商方案讲标 | E16: 演示评分表 | G16: 否 | M16: =IFERROR(IF(OR(J16="",L16=""),"",L16-J16),"") | O16: =IF(N16=100,"已完成",IF(AND(N16=0,J16<>"",TODAY()>J16),"已延期",IF(N16=0,"未开始",IF(AND(J16<>"",TODAY()>J16),"已延期","进行中")))) -> 未开始
A17: 2.选型 | B17: 2.2.2 | C17: POC概念验证(可选) | D17: 关键场景实机验证 | E17: POC报告 | G17: 否 | H17: 2.2.1 | M17: =IFERROR(IF(OR(J17="",L17=""),"",L17-J17),"") | O17: =IF(N17=100,"已完成",IF(AND(N17=0,J17<>"",TODAY()>J17),"已延期",IF(N17=0,"未开始",IF(AND(J17<>"",TODAY()>J17),"已延期","进行中")))) -> 未开始
A18: 2.选型 | B18: 2.2.3 | C18: 评标与供应商选定 | D18: 技术+商务综合评分 | E18: 中选通知(里程碑) | G18: 是 | H18: 2.2.2 | M18: =IFERROR(IF(OR(J18="",L18=""),"",L18-J18),"") | O18: =IF(N18=100,"已完成",IF(AND(N18=0,J18<>"",TODAY()>J18),"已延期",IF(N18=0,"未开始",IF(AND(J18<>"",TODAY()>J18),"已延期","进行中")))) -> 未开始
A19: 2.选型 | B19: 2.3 | C19: 合同与商务 | D19: 含谈判、SOW、SLA、付款节点 | E19: 合同签署 | G19: 否 | H19: 2.2.3 | M19: =IFERROR(IF(OR(J19="",L19=""),"",L19-J19),"") | O19: =IF(N19=100,"已完成",IF(AND(N19=0,J19<>"",TODAY()>J19),"已延期",IF(N19=0,"未开始",IF(AND(J19<>"",TODAY()>J19),"已延期","进行中")))) -> 未开始
A20: 2.选型 | B20: 2.3.1 | C20: 商务谈判与SOW | D20: 价格、范围、交付物清单 | E20: SOW确认 | G20: 否 | M20: =IFERROR(IF(OR(J20="",L20=""),"",L20-J20),"") | O20: =IF(N20=100,"已完成",IF(AND(N20=0,J20<>"",TODAY()>J20),"已延期",IF(N20=0,"未开始",IF(AND(J20<>"",TODAY()>J20),"已延期","进行中")))) -> 未开始
A21: 2.选型 | B21: 2.3.2 | C21: SLA与验收条款 | D21: 服务级别、验收标准、罚则 | E21: SLA附件确认 | G21: 否 | H21: 2.3.1 | M21: =IFERROR(IF(OR(J21="",L21=""),"",L21-J21),"") | O21: =IF(N21=100,"已完成",IF(AND(N21=0,J21<>"",TODAY()>J21),"已延期",IF(N21=0,"未开始",IF(AND(J21<>"",TODAY()>J21),"已延期","进行中")))) -> 未开始
A22: 2.选型 | B22: 2.3.3 | C22: 合同签署 | D22: 法务、用印 | E22: 合同生效(里程碑) | G22: 是 | H22: 2.3.2 | M22: =IFERROR(IF(OR(J22="",L22=""),"",L22-J22),"") | O22: =IF(N22=100,"已完成",IF(AND(N22=0,J22<>"",TODAY()>J22),"已延期",IF(N22=0,"未开始",IF(AND(J22<>"",TODAY()>J22),"已延期","进行中")))) -> 未开始
A23: 3.设计 | B23: 3 | C23: 蓝图设计与方案确认 | D23: 含调研、蓝图、差距分析、定制需求确认 | E23: 蓝图方案签字 | G23: 否 | H23: 2.3.3 | M23: =IFERROR(IF(OR(J23="",L23=""),"",L23-J23),"") | O23: =IF(N23=100,"已完成",IF(AND(N23=0,J23<>"",TODAY()>J23),"已延期",IF(N23=0,"未开始",IF(AND(J23<>"",TODAY()>J23),"已延期","进行中")))) -> 未开始
A24: 3.设计 | B24: 3.1 | C24: 业务调研与蓝图(Blueprint) | D24: 供应商主导的业务流程调研 | E24: 蓝图文档签字 | G24: 否 | M24: =IFERROR(IF(OR(J24="",L24=""),"",L24-J24),"") | O24: =IF(N24=100,"已完成",IF(AND(N24=0,J24<>"",TODAY()>J24),"已延期",IF(N24=0,"未开始",IF(AND(J24<>"",TODAY()>J24),"已延期","进行中")))) -> 未开始
A25: 3.设计 | B25: 3.1.1 | C25: 业务流程调研(As-Is) | D25: 现状流程、痛点梳理 | E25: 调研报告 | G25: 否 | M25: =IFERROR(IF(OR(J25="",L25=""),"",L25-J25),"") | O25: =IF(N25=100,"已完成",IF(AND(N25=0,J25<>"",TODAY()>J25),"已延期",IF(N25=0,"未开始",IF(AND(J25<>"",TODAY()>J25),"已延期","进行中")))) -> 未开始
A26: 3.设计 | B26: 3.1.2 | C26: To-Be流程与蓝图设计 | D26: 目标流程、系统匹配 | E26: 蓝图文档评审 | G26: 否 | H26: 3.1.1 | M26: =IFERROR(IF(OR(J26="",L26=""),"",L26-J26),"") | O26: =IF(N26=100,"已完成",IF(AND(N26=0,J26<>"",TODAY()>J26),"已延期",IF(N26=0,"未开始",IF(AND(J26<>"",TODAY()>J26),"已延期","进行中")))) -> 未开始
A27: 3.设计 | B27: 3.1.3 | C27: 蓝图确认与签字 | D27: 业务方确认 | E27: 蓝图签字(里程碑) | G27: 是 | H27: 3.1.2 | M27: =IFERROR(IF(OR(J27="",L27=""),"",L27-J27),"") | O27: =IF(N27=100,"已完成",IF(AND(N27=0,J27<>"",TODAY()>J27),"已延期",IF(N27=0,"未开始",IF(AND(J27<>"",TODAY()>J27),"已延期","进行中")))) -> 未开始
A28: 3.设计 | B28: 3.2 | C28: 差距分析与定制需求 | D28: 标准功能与需求差距(Fit-Gap) | E28: 定制清单确认 | G28: 否 | H28: 3.1.3 | M28: =IFERROR(IF(OR(J28="",L28=""),"",L28-J28),"") | O28: =IF(N28=100,"已完成",IF(AND(N28=0,J28<>"",TODAY()>J28),"已延期",IF(N28=0,"未开始",IF(AND(J28<>"",TODAY()>J28),"已延期","进行中")))) -> 未开始
A29: 3.设计 | B29: 3.2.1 | C29: Fit-Gap差距分析 | D29: 标准功能覆盖度评估 | E29: Fit-Gap报告 | G29: 否 | M29: =IFERROR(IF(OR(J29="",L29=""),"",L29-J29),"") | O29: =IF(N29=100,"已完成",IF(AND(N29=0,J29<>"",TODAY()>J29),"已延期",IF(N29=0,"未开始",IF(AND(J29<>"",TODAY()>J29),"已延期","进行中")))) -> 未开始
A30: 3.设计 | B30: 3.2.2 | C30: 定制开发需求确认与报价 | D30: 定制清单、工作量、费用 | E30: 变更/补充协议 | G30: 否 | H30: 3.2.1 | M30: =IFERROR(IF(OR(J30="",L30=""),"",L30-J30),"") | O30: =IF(N30=100,"已完成",IF(AND(N30=0,J30<>"",TODAY()>J30),"已延期",IF(N30=0,"未开始",IF(AND(J30<>"",TODAY()>J30),"已延期","进行中")))) -> 未开始
A31: 3.设计 | B31: 3.3 | C31: 技术架构与集成设计 | D31: 部署架构、接口、安全、性能 | E31: 技术方案评审通过 | G31: 否 | H31: 3.1.3 | M31: =IFERROR(IF(OR(J31="",L31=""),"",L31-J31),"") | O31: =IF(N31=100,"已完成",IF(AND(N31=0,J31<>"",TODAY()>J31),"已延期",IF(N31=0,"未开始",IF(AND(J31<>"",TODAY()>J31),"已延期","进行中")))) -> 未开始
A32: 3.设计 | B32: 3.3.1 | C32: 系统部署架构设计 | D32: 云/本地、环境规划、高可用 | E32: 架构文档评审 | G32: 否 | M32: =IFERROR(IF(OR(J32="",L32=""),"",L32-J32),"") | O32: =IF(N32=100,"已完成",IF(AND(N32=0,J32<>"",TODAY()>J32),"已延期",IF(N32=0,"未开始",IF(AND(J32<>"",TODAY()>J32),"已延期","进行中")))) -> 未开始
A33: 3.设计 | B33: 3.3.2 | C33: 接口/集成方案设计 | D33: 与现有系统(ERP/OA/SSO等)接口 | E33: 接口设计文档 | G33: 否 | H33: 3.3.1 | M33: =IFERROR(IF(OR(J33="",L33=""),"",L33-J33),"") | O33: =IF(N33=100,"已完成",IF(AND(N33=0,J33<>"",TODAY()>J33),"已延期",IF(N33=0,"未开始",IF(AND(J33<>"",TODAY()>J33),"已延期","进行中")))) -> 未开始
A34: 3.设计 | B34: 3.3.3 | C34: 信息安全与合规评审 | D34: 权限、日志、数据合规(个保法) | E34: 安全评审通过 | G34: 否 | H34: 3.3.1 | M34: =IFERROR(IF(OR(J34="",L34=""),"",L34-J34),"") | O34: =IF(N34=100,"已完成",IF(AND(N34=0,J34<>"",TODAY()>J34),"已延期",IF(N34=0,"未开始",IF(AND(J34<>"",TODAY()>J34),"已延期","进行中")))) -> 未开始
A35: 4.实现 | B35: 4 | C35: 系统实现与配置 | D35: 含供应商配置、定制开发、环境搭建 | E35: 系统进入测试就绪 | G35: 否 | H35: 3.2.2 | M35: =IFERROR(IF(OR(J35="",L35=""),"",L35-J35),"") | O35: =IF(N35=100,"已完成",IF(AND(N35=0,J35<>"",TODAY()>J35),"已延期",IF(N35=0,"未开始",IF(AND(J35<>"",TODAY()>J35),"已延期","进行中")))) -> 未开始
A36: 4.实现 | B36: 4.1 | C36: 环境准备 | D36: 含开发/测试/生产环境 | E36: 环境验收通过 | G36: 否 | M36: =IFERROR(IF(OR(J36="",L36=""),"",L36-J36),"") | O36: =IF(N36=100,"已完成",IF(AND(N36=0,J36<>"",TODAY()>J36),"已延期",IF(N36=0,"未开始",IF(AND(J36<>"",TODAY()>J36),"已延期","进行中")))) -> 未开始
A37: 4.实现 | B37: 4.1.1 | C37: 硬件/云资源与网络就绪 | D37: 服务器、网络、存储、账号 | E37: 资源交付清单 | G37: 否 | M37: =IFERROR(IF(OR(J37="",L37=""),"",L37-J37),"") | O37: =IF(N37=100,"已完成",IF(AND(N37=0,J37<>"",TODAY()>J37),"已延期",IF(N37=0,"未开始",IF(AND(J37<>"",TODAY()>J37),"已延期","进行中")))) -> 未开始
A38: 4.实现 | B38: 4.1.2 | C38: 开发/测试环境搭建 | D38: 环境部署与连通性验证 | E38: 环境验收单 | G38: 否 | H38: 4.1.1 | M38: =IFERROR(IF(OR(J38="",L38=""),"",L38-J38),"") | O38: =IF(N38=100,"已完成",IF(AND(N38=0,J38<>"",TODAY()>J38),"已延期",IF(N38=0,"未开始",IF(AND(J38<>"",TODAY()>J38),"已延期","进行中")))) -> 未开始
A39: 4.实现 | B39: 4.1.3 | C39: 生产环境搭建 | D39: 生产部署、备份、监控 | E39: 生产环境就绪 | G39: 否 | H39: 4.1.2 | M39: =IFERROR(IF(OR(J39="",L39=""),"",L39-J39),"") | O39: =IF(N39=100,"已完成",IF(AND(N39=0,J39<>"",TODAY()>J39),"已延期",IF(N39=0,"未开始",IF(AND(J39<>"",TODAY()>J39),"已延期","进行中")))) -> 未开始
A40: 4.实现 | B40: 4.2 | C40: 系统配置与定制开发 | D40: 供应商交付主体 | E40: 模块自测通过 | G40: 否 | H40: 4.1.2 | M40: =IFERROR(IF(OR(J40="",L40=""),"",L40-J40),"") | O40: =IF(N40=100,"已完成",IF(AND(N40=0,J40<>"",TODAY()>J40),"已延期",IF(N40=0,"未开始",IF(AND(J40<>"",TODAY()>J40),"已延期","进行中")))) -> 未开始
...

Sheet 里程碑跟踪
A1: WBS编号 | B1: 里程碑名称 | C1: 阶段 | D1: 责任人 | E1: 计划结束 | F1: 实际结束 | G1: 偏差(天) | H1: 状态
A2: =WBS主表!B6 -> 1.1.3 | B2: =WBS主表!C6 -> 立项评审与审批 | C2: =WBS主表!A6 -> 1.立项 | D2: =IF(WBS主表!F6="","(待填)",WBS主表!F6) -> (待填) | E2: =IF(WBS主表!J6="","",WBS主表!J6) | F2: =IF(WBS主表!L6="","",WBS主表!L6) | G2: =IFERROR(IF(OR(WBS主表!J6="",WBS主表!L6=""),"",WBS主表!L6-WBS主表!J6),"") | H2: =WBS主表!O6 -> 未开始
A3: =WBS主表!B10 -> 1.2.3 | B3: =WBS主表!C10 -> 项目启动会(Kick-off) | C3: =WBS主表!A10 -> 1.立项 | D3: =IF(WBS主表!F10="","(待填)",WBS主表!F10) -> (待填) | E3: =IF(WBS主表!J10="","",WBS主表!J10) | F3: =IF(WBS主表!L10="","",WBS主表!L10) | G3: =IFERROR(IF(OR(WBS主表!J10="",WBS主表!L10=""),"",WBS主表!L10-WBS主表!J10),"") | H3: =WBS主表!O10 -> 未开始
A4: =WBS主表!B18 -> 2.2.3 | B4: =WBS主表!C18 -> 评标与供应商选定 | C4: =WBS主表!A18 -> 2.选型 | D4: =IF(WBS主表!F18="","(待填)",WBS主表!F18) -> (待填) | E4: =IF(WBS主表!J18="","",WBS主表!J18) | F4: =IF(WBS主表!L18="","",WBS主表!L18) | G4: =IFERROR(IF(OR(WBS主表!J18="",WBS主表!L18=""),"",WBS主表!L18-WBS主表!J18),"") | H4: =WBS主表!O18 -> 未开始
A5: =WBS主表!B22 -> 2.3.3 | B5: =WBS主表!C22 -> 合同签署 | C5: =WBS主表!A22 -> 2.选型 | D5: =IF(WBS主表!F22="","(待填)",WBS主表!F22) -> (待填) | E5: =IF(WBS主表!J22="","",WBS主表!J22) | F5: =IF(WBS主表!L22="","",WBS主表!L22) | G5: =IFERROR(IF(OR(WBS主表!J22="",WBS主表!L22=""),"",WBS主表!L22-WBS主表!J22),"") | H5: =WBS主表!O22 -> 未开始
A6: =WBS主表!B27 -> 3.1.3 | B6: =WBS主表!C27 -> 蓝图确认与签字 | C6: =WBS主表!A27 -> 3.设计 | D6: =IF(WBS主表!F27="","(待填)",WBS主表!F27) -> (待填) | E6: =IF(WBS主表!J27="","",WBS主表!J27) | F6: =IF(WBS主表!L27="","",WBS主表!L27) | G6: =IFERROR(IF(OR(WBS主表!J27="",WBS主表!L27=""),"",WBS主表!L27-WBS主表!J27),"") | H6: =WBS主表!O27 -> 未开始
A7: =WBS主表!B59 -> 5.3.3 | B7: =WBS主表!C59 -> UAT签字确认 | C7: =WBS主表!A59 -> 5.测试 | D7: =IF(WBS主表!F59="","(待填)",WBS主表!F59) -> (待填) | E7: =IF(WBS主表!J59="","",WBS主表!J59) | F7: =IF(WBS主表!L59="","",WBS主表!L59) | G7: =IFERROR(IF(OR(WBS主表!J59="",WBS主表!L59=""),"",WBS主表!L59-WBS主表!J59),"") | H7: =WBS主表!O59 -> 未开始
A8: =WBS主表!B73 -> 6.3.3 | B8: =WBS主表!C73 -> 系统正式上线(Go-Live) | C8: =WBS主表!A73 -> 6.上线 | D8: =IF(WBS主表!F73="","(待填)",WBS主表!F73) -> (待填) | E8: =IF(WBS主表!J73="","",WBS主表!J73) | F8: =IF(WBS主表!L73="","",WBS主表!L73) | G8: =IFERROR(IF(OR(WBS主表!J73="",WBS主表!L73=""),"",WBS主表!L73-WBS主表!J73),"") | H8: =WBS主表!O73 -> 未开始
A9: =WBS主表!B82 -> 7.3.1 | B9: =WBS主表!C82 -> 项目终验与验收报告 | C9: =WBS主表!A82 -> 7.收尾 | D9: =IF(WBS主表!F82="","(待填)",WBS主表!F82) -> (待填) | E9: =IF(WBS主表!J82="","",WBS主表!J82) | F9: =IF(WBS主表!L82="","",WBS主表!L82) | G9: =IFERROR(IF(OR(WBS主表!J82="",WBS主表!L82=""),"",WBS主表!L82-WBS主表!J82),"") | H9: =WBS主表!O82 -> 未开始
A10: =WBS主表!B84 -> 7.3.3 | B10: =WBS主表!C84 -> 项目复盘与结项 | C10: =WBS主表!A84 -> 7.收尾 | D10: =IF(WBS主表!F84="","(待填)",WBS主表!F84) -> (待填) | E10: =IF(WBS主表!J84="","",WBS主表!J84) | F10: =IF(WBS主表!L84="","",WBS主表!L84) | G10: =IFERROR(IF(OR(WBS主表!J84="",WBS主表!L84=""),"",WBS主表!L84-WBS主表!J84),"") | H10: =WBS主表!O84 -> 未开始

Sheet 字段说明与用法
A1: 字段说明与使用规范
A2: 字段 | B2: 类别 | C2: 填写方式 | D2: 说明 / PMO用途
A3: 阶段 | B3: 结构 | C3: 手工 | D3: 便于按阶段筛选与汇报
A4: WBS编号 | B4: 结构 | C4: 手工 | D4: 层级式编号(1/1.1/1.1.1)，全表主键；本模板分解至第3层工作包
A5: 任务名称(交付物) | B5: 结构 | C5: 手工 | D5: ★用名词性交付物命名(如“需求规格说明书”)，而非动词(“编写需求”)——WBS分解的是成果，不是活动
A6: WBS词典说明 | B6: 结构 | C6: 手工 | D6: ★写清“含什么/不含什么”。边界不清是项目扯皮与失控的头号根源，务必填写
A7: 交付物/验收标准(DoD) | B7: 结构 | C7: 手工 | D7: 完成的定义。没有DoD，“完成80%”就是空话
A8: 责任人 | B8: 责任 | C8: 手工 | D8: ★一个工作包只能有一个责任人(唯一)，这是纪律问题
A9: 里程碑 | B9: 进度 | C9: 下拉 | D9: 是/否；勾选“是”的行会自动出现在“里程碑跟踪”页并加粗标红
A10: 优先级 | B10: 管理 | C10: 下拉 | D10: 高/中/低；资源冲突时的排序依据
A11: 前置任务(WBS号) | B11: 进度 | C11: 手工 | D11: 填前置任务WBS编号，是排关键路径的前提；无依赖则留空
A12: 计划开始/结束 | B12: 进度 | C12: 手工 | D12: 当前计划日期，可随变更更新
A13: 实际开始/结束 | B13: 进度 | C13: 手工 | D13: 实际发生日期，用于计算偏差
... A18: 备注 | B18: 其他 | C18: 手工 | D18: 补充说明
A20: 三条实践提醒（比字段本身更重要）
A21: 1. 字段宁少勿多：字段越多，一线越不愿更新；数据不更新，PMO看到的就是假进度。本模板已控制在必备+进度层，跑顺后再按需增列(如成本、RACI四列)。
A22: 2. 完成度务必定死口径：采用0/50/100三档法，配合8~80原则把工作包拆小，杜绝“完成90%”长期挂账。
A23: 3. 付款与里程碑挂钩：建议将合同付款节点与本表里程碑(K列=是)对齐，用“里程碑跟踪”页做供应商履约与付款控制。
